Backup failed for Site library.system. Database or site_config.json may be corrupted
Traceback with variables (most recent call last):
  File "apps/frappe/frappe/commands/site.py", line 934, in backup
    odb = scheduled_backup(
      context = {'sites': ['library.system'], 'force': False, 'verbose': True, 'profile': False}
      with_files = False
      backup_path = None
      backup_path_db = None
      backup_path_files = None
      backup_path_private_files = None
      backup_path_conf = None
      ignore_backup_conf = False
      verbose = True
      compress = False
      include = ''
      exclude = ''
      old_backup_metadata = False
      scheduled_backup = <function scheduled_backup at 0x1118a9120>
      exit_code = 0
      rollback_callback = None
      site = 'library.system'
  File "apps/frappe/frappe/utils/backups.py", line 568, in scheduled_backup
    return new_backup(
      older_than = 6
      ignore_files = True
      backup_path = None
      backup_path_db = None
      backup_path_files = None
      backup_path_private_files = None
      backup_path_conf = None
      ignore_conf = False
      include_doctypes = ''
      exclude_doctypes = ''
      compress = False
      force = True
      verbose = True
      old_backup_metadata = False
      rollback_callback = <frappe.utils.CallbackManager object at 0x111a8f0a0>
  File "apps/frappe/frappe/utils/backups.py", line 626, in new_backup
    odb.get_backup(older_than, ignore_files, force=force)
      older_than = 6
      ignore_files = True
      backup_path = None
      backup_path_db = None
      backup_path_files = None
      backup_path_private_files = None
      backup_path_conf = None
      ignore_conf = False
      include_doctypes = ''
      exclude_doctypes = ''
      compress = False
      force = True
      verbose = True
      old_backup_metadata = False
      rollback_callback = <frappe.utils.CallbackManager object at 0x111a8f0a0>
      odb = <frappe.utils.backups.BackupGenerator object at 0x1119f5be0>
  File "apps/frappe/frappe/utils/backups.py", line 191, in get_backup
    self.delete_if_step_fails(self.take_dump, self.backup_path_db)
      self = <frappe.utils.backups.BackupGenerator object at 0x1119f5be0>
      older_than = 6
      ignore_files = True
      force = True
      last_db = False
      last_file = False
      last_private_file = False
      site_config_backup_path = False
  File "apps/frappe/frappe/utils/backups.py", line 507, in delete_if_step_fails
    raise e
      self = <frappe.utils.backups.BackupGenerator object at 0x1119f5be0>
      step = <bound method BackupGenerator.take_dump of <frappe.utils.backups.BackupGenerator object at 0x1119f5be0>>
      paths = ('./library.system/private/backups/20240429_180003-library_system-database.sql.gz',)
      path = './library.system/private/backups/20240429_180003-library_system-database.sql.gz'
  File "apps/frappe/frappe/utils/backups.py", line 502, in delete_if_step_fails
    step()
      self = <frappe.utils.backups.BackupGenerator object at 0x1119f5be0>
      step = <bound method BackupGenerator.take_dump of <frappe.utils.backups.BackupGenerator object at 0x1119f5be0>>
      paths = ('./library.system/private/backups/20240429_180003-library_system-database.sql.gz',)
      path = './library.system/private/backups/20240429_180003-library_system-database.sql.gz'
  File "apps/frappe/frappe/utils/backups.py", line 444, in take_dump
    frappe.throw(
      self = <frappe.utils.backups.BackupGenerator object at 0x1119f5be0>
      shlex = <module 'shlex' from '/usr/local/Cellar/python@3.12/3.12.3/Frameworks/Python.framework/Versions/3.12/lib/python3.12/shlex.py'>
      frappe = <module 'frappe' from 'apps/frappe/frappe/__init__.py'>
      get_app_branch = <function get_app_branch at 0x10e72a7a0>
      gzip_exc = '/usr/bin/gzip'
      database_header_content = ['begin frappe metadata', '[frappe]', 'version = 16.0.0-dev', 'branch = develop', 'end frappe metadata', '']
      generated_header = '-- begin frappe metadata\n-- [frappe]\n-- version = 16.0.0-dev\n-- branch = develop\n-- end frappe metadata\n-- \n'
      f = <_io.TextIOWrapper name='./library.system/private/backups/20240429_180003-library_system-database.sql.gz' encoding='UTF-8'>
      cmd = []
      extra = []
      get_command = <function get_command at 0x1118f0220>
      bin = None
      args = ['--user=_2878a7a8a2db0432', '--host=127.0.0.1', '--port=3306', '--password=209K3PbbGNZCp8Id', '--single-transaction', '--quick', '--lock-tables=false', '_2878a7a8a2db0432']
      bin_name = 'mariadb-dump'
  File "apps/frappe/frappe/__init__.py", line 681, in throw
    msgprint(
      msg = 'mariadb-dump not found in PATH! This is required to take a backup.'
      exc = <class 'frappe.exceptions.ExecutableNotFound'>
      title = None
      is_minimizable = False
      wide = False
      as_list = False
      primary_action = None
  File "apps/frappe/frappe/__init__.py", line 646, in msgprint
    _raise_exception()
      msg = 'mariadb-dump not found in PATH! This is required to take a backup.'
      title = None
      raise_exception = <class 'frappe.exceptions.ExecutableNotFound'>
      as_table = False
      as_list = False
      indicator = 'red'
      alert = False
      primary_action = None
      is_minimizable = False
      wide = False
      realtime = False
      _raise_exception = <function msgprint.<locals>._raise_exception at 0x10e72b740>
      inspect = <module 'inspect' from '/usr/local/Cellar/python@3.12/3.12.3/Frameworks/Python.framework/Versions/3.12/lib/python3.12/inspect.py'>
      out = {'message': 'mariadb-dump not found in PATH! This is required to take a backup.', 'title': 'Message', 'indicator': 'red', 'raise_exception': 1, '__frappe_exc_id': '0c200472d4a0a11fa4ab3dffcd667be474db1b49853b0476eec2f315'}
  File "apps/frappe/frappe/__init__.py", line 597, in _raise_exception
    raise exc
      exc = ExecutableNotFound('mariadb-dump not found in PATH! This is required to take a backup.')
      inspect = <module 'inspect' from '/usr/local/Cellar/python@3.12/3.12.3/Frameworks/Python.framework/Versions/3.12/lib/python3.12/inspect.py'>
      msg = 'mariadb-dump not found in PATH! This is required to take a backup.'
      out = {'message': 'mariadb-dump not found in PATH! This is required to take a backup.', 'title': 'Message', 'indicator': 'red', 'raise_exception': 1, '__frappe_exc_id': '0c200472d4a0a11fa4ab3dffcd667be474db1b49853b0476eec2f315'}
      raise_exception = <class 'frappe.exceptions.ExecutableNotFound'>
frappe.exceptions.ExecutableNotFound: mariadb-dump not found in PATH! This is required to take a backup.
Backup failed for Site library.system. Database or site_config.json may be corrupted
Traceback with variables (most recent call last):
  File "apps/frappe/frappe/commands/site.py", line 934, in backup
    odb = scheduled_backup(
      context = {'sites': ['library.system'], 'force': False, 'verbose': True, 'profile': False}
      with_files = False
      backup_path = None
      backup_path_db = None
      backup_path_files = None
      backup_path_private_files = None
      backup_path_conf = None
      ignore_backup_conf = False
      verbose = True
      compress = False
      include = ''
      exclude = ''
      old_backup_metadata = False
      scheduled_backup = <function scheduled_backup at 0x10cbf1120>
      exit_code = 0
      rollback_callback = None
      site = 'library.system'
  File "apps/frappe/frappe/utils/backups.py", line 568, in scheduled_backup
    return new_backup(
      older_than = 6
      ignore_files = True
      backup_path = None
      backup_path_db = None
      backup_path_files = None
      backup_path_private_files = None
      backup_path_conf = None
      ignore_conf = False
      include_doctypes = ''
      exclude_doctypes = ''
      compress = False
      force = True
      verbose = True
      old_backup_metadata = False
      rollback_callback = <frappe.utils.CallbackManager object at 0x10cddb460>
  File "apps/frappe/frappe/utils/backups.py", line 626, in new_backup
    odb.get_backup(older_than, ignore_files, force=force)
      older_than = 6
      ignore_files = True
      backup_path = None
      backup_path_db = None
      backup_path_files = None
      backup_path_private_files = None
      backup_path_conf = None
      ignore_conf = False
      include_doctypes = ''
      exclude_doctypes = ''
      compress = False
      force = True
      verbose = True
      old_backup_metadata = False
      rollback_callback = <frappe.utils.CallbackManager object at 0x10cddb460>
      odb = <frappe.utils.backups.BackupGenerator object at 0x1086bed80>
  File "apps/frappe/frappe/utils/backups.py", line 191, in get_backup
    self.delete_if_step_fails(self.take_dump, self.backup_path_db)
      self = <frappe.utils.backups.BackupGenerator object at 0x1086bed80>
      older_than = 6
      ignore_files = True
      force = True
      last_db = False
      last_file = False
      last_private_file = False
      site_config_backup_path = False
  File "apps/frappe/frappe/utils/backups.py", line 507, in delete_if_step_fails
    raise e
      self = <frappe.utils.backups.BackupGenerator object at 0x1086bed80>
      step = <bound method BackupGenerator.take_dump of <frappe.utils.backups.BackupGenerator object at 0x1086bed80>>
      paths = ('./library.system/private/backups/20240430_000002-library_system-database.sql.gz',)
      path = './library.system/private/backups/20240430_000002-library_system-database.sql.gz'
  File "apps/frappe/frappe/utils/backups.py", line 502, in delete_if_step_fails
    step()
      self = <frappe.utils.backups.BackupGenerator object at 0x1086bed80>
      step = <bound method BackupGenerator.take_dump of <frappe.utils.backups.BackupGenerator object at 0x1086bed80>>
      paths = ('./library.system/private/backups/20240430_000002-library_system-database.sql.gz',)
      path = './library.system/private/backups/20240430_000002-library_system-database.sql.gz'
  File "apps/frappe/frappe/utils/backups.py", line 444, in take_dump
    frappe.throw(
      self = <frappe.utils.backups.BackupGenerator object at 0x1086bed80>
      shlex = <module 'shlex' from '/usr/local/Cellar/python@3.12/3.12.3/Frameworks/Python.framework/Versions/3.12/lib/python3.12/shlex.py'>
      frappe = <module 'frappe' from 'apps/frappe/frappe/__init__.py'>
      get_app_branch = <function get_app_branch at 0x109a827a0>
      gzip_exc = '/usr/bin/gzip'
      database_header_content = ['begin frappe metadata', '[frappe]', 'version = 16.0.0-dev', 'branch = develop', 'end frappe metadata', '']
      generated_header = '-- begin frappe metadata\n-- [frappe]\n-- version = 16.0.0-dev\n-- branch = develop\n-- end frappe metadata\n-- \n'
      f = <_io.TextIOWrapper name='./library.system/private/backups/20240430_000002-library_system-database.sql.gz' encoding='UTF-8'>
      cmd = []
      extra = []
      get_command = <function get_command at 0x10cc40220>
      bin = None
      args = ['--user=_2878a7a8a2db0432', '--host=127.0.0.1', '--port=3306', '--password=209K3PbbGNZCp8Id', '--single-transaction', '--quick', '--lock-tables=false', '_2878a7a8a2db0432']
      bin_name = 'mariadb-dump'
  File "apps/frappe/frappe/__init__.py", line 681, in throw
    msgprint(
      msg = 'mariadb-dump not found in PATH! This is required to take a backup.'
      exc = <class 'frappe.exceptions.ExecutableNotFound'>
      title = None
      is_minimizable = False
      wide = False
      as_list = False
      primary_action = None
  File "apps/frappe/frappe/__init__.py", line 646, in msgprint
    _raise_exception()
      msg = 'mariadb-dump not found in PATH! This is required to take a backup.'
      title = None
      raise_exception = <class 'frappe.exceptions.ExecutableNotFound'>
      as_table = False
      as_list = False
      indicator = 'red'
      alert = False
      primary_action = None
      is_minimizable = False
      wide = False
      realtime = False
      _raise_exception = <function msgprint.<locals>._raise_exception at 0x109a83740>
      inspect = <module 'inspect' from '/usr/local/Cellar/python@3.12/3.12.3/Frameworks/Python.framework/Versions/3.12/lib/python3.12/inspect.py'>
      out = {'message': 'mariadb-dump not found in PATH! This is required to take a backup.', 'title': 'Message', 'indicator': 'red', 'raise_exception': 1, '__frappe_exc_id': '822513816fe7d02312f7f8e8cafb882bd6bdf47a34ab7bd9ec947dc7'}
  File "apps/frappe/frappe/__init__.py", line 597, in _raise_exception
    raise exc
      exc = ExecutableNotFound('mariadb-dump not found in PATH! This is required to take a backup.')
      inspect = <module 'inspect' from '/usr/local/Cellar/python@3.12/3.12.3/Frameworks/Python.framework/Versions/3.12/lib/python3.12/inspect.py'>
      msg = 'mariadb-dump not found in PATH! This is required to take a backup.'
      out = {'message': 'mariadb-dump not found in PATH! This is required to take a backup.', 'title': 'Message', 'indicator': 'red', 'raise_exception': 1, '__frappe_exc_id': '822513816fe7d02312f7f8e8cafb882bd6bdf47a34ab7bd9ec947dc7'}
      raise_exception = <class 'frappe.exceptions.ExecutableNotFound'>
frappe.exceptions.ExecutableNotFound: mariadb-dump not found in PATH! This is required to take a backup.
